Workbook

Sheet Dashboard
B1: AboRadar
B2: Dein Abo-Dashboard – Alles auf einen Blick
B4: Monatliche Kosten | C4: Aktive Abos | D4: Verschwendet/Monat | E4: Verschwendet/Jahr
B5: ='Abo-Tracker'!D12 | C5: =COUNTIF('Abo-Tracker'!F5:F9,"Aktiv") | D5: ='Abo-Tracker'!D13 | E5: ='Abo-Tracker'!D14
B8: Kosten nach Kategorie | D8: Deine Top-Abos | G8: Kategorie | H8: Kosten
G9: Streaming | H9: =SUMIF('Abo-Tracker'!C5:C9,G9,'Abo-Tracker'!D5:D9)
G10: Software | H10: =SUMIF('Abo-Tracker'!C5:C9,G10,'Abo-Tracker'!D5:D9)
G11: Fitness | H11: =SUMIF('Abo-Tracker'!C5:C9,G11,'Abo-Tracker'!D5:D9)
G12: Cloud | H12: =SUMIF('Abo-Tracker'!C5:C9,G12,'Abo-Tracker'!D5:D9)
G13: News | H13: =SUMIF('Abo-Tracker'!C5:C9,G13,'Abo-Tracker'!D5:D9)
G14: Gaming | H14: =SUMIF('Abo-Tracker'!C5:C9,G14,'Abo-Tracker'!D5:D9)
G15: Lieferdienste | H15: =SUMIF('Abo-Tracker'!C5:C9,G15,'Abo-Tracker'!D5:D9)
G16: Sonstiges | H16: =SUMIF('Abo-Tracker'!C5:C9,G16,'Abo-Tracker'!D5:D9)
G18: Abo | H18: Kosten
G19: ='Abo-Tracker'!B5 | H19: ='Abo-Tracker'!D5
G20: ='Abo-Tracker'!B6 | H20: ='Abo-Tracker'!D6
G21: ='Abo-Tracker'!B7 | H21: ='Abo-Tracker'!D7
G22: ='Abo-Tracker'!B8 | H22: ='Abo-Tracker'!D8
G23: ='Abo-Tracker'!B9 | H23: ='Abo-Tracker'!D9
B25: Abo-Status Übersicht
B26: ✅ Aktiv | C26: ⚠️ Ungenutzt | D26: ❌ Gekündigt | E26: 📊 Gesamt
B27: =COUNTIF('Abo-Tracker'!F5:F9,"Aktiv") | C27: =COUNTIF('Abo-Tracker'!F5:F9,"Ungenutzt") | D27: =COUNTIF('Abo-Tracker'!F5:F9,"Gekündigt") | E27: =COUNTA('Abo-Tracker'!B5:B9)
B30: AboRadar Freebie – Upgrade auf Pro für unbegrenzte Abos → aboradar.app

Sheet Abo-Tracker
A1: 📊 AboRadar – Abo-Tracker
A2: Trage hier deine Abos ein (max. 5 im Freebie). Alle Felder in den grünen Spalten sind editierbar.
A4: Nr. | B4: Abo-Name | C4: Kategorie | D4: Mtl. Kosten (€) | E4: Zahlungsintervall | F4: Status | G4: Kündigungsfrist | H4: Nächste Kündigung | I4: Notizen
A5: 1 | B5: Netflix | C5: Streaming | D5: 12.99 | E5: Monatlich | F5: Aktiv | G5: Jederzeit | H5: — | I5: Standard-Abo
A6: 2 | B6: Spotify | C6: Streaming | D6: 9.99 | E6: Monatlich | F6: Aktiv | G6: Jederzeit | H6: — | I6: Family Plan
A7: 3 | B7: McFit | C7: Fitness | D7: 24.99 | E7: Monatlich | F7: Ungenutzt | G7: 3 Monate | H7: 30.06.2026 | I7: Seit 4 Monaten nicht mehr gewesen!
A8: 4 | B8: Adobe Creative Cloud | C8: Software | D8: 23.79 | E8: Monatlich | F8: Aktiv | G8: 14 Tage | H8: — | I8: Foto-Abo
A9: 5 | B9: iCloud+ | C9: Cloud | D9: 2.99 | E9: Monatlich | F9: Aktiv | G9: Jederzeit | H9: — | I9: 200 GB
C12: Gesamt monatlich: | D12: =SUM(D5:D9)
C13: Davon ungenutzt: | D13: =SUMIF(F5:F9,"Ungenutzt",D5:D9)
C14: Verschwendung/Jahr: | D14: =D13*12
A17: 💡 Du brauchst mehr als 5 Abos? Upgrade auf AboRadar Pro (14,95 € einmalig) → aboradar.app

Sheet Abo-Finder
B1: 🔍 Abo-Finder – Checkliste
B2: Geh die Liste durch und markiere alle Dienste, die du abonniert hast.
B3: 💡 Vorher: 1) Kontoauszüge checken 2) E-Mail nach 'Rechnung' durchsuchen 3) App-Store Abos prüfen
B5: Kategorie | C5: Dienst | D5: Hast du? | E5: Mtl. Kosten (€)
B6: Streaming Video
C7: Netflix | D7: Nein
C8: Disney+ | D8: Nein
C9: Amazon Prime Video | D9: Nein
C10: Sky / WOW | D10: Nein
C11: DAZN | D11: Nein
C12: RTL+ | D12: Nein
C13: Paramount+ | D13: Nein
C14: Apple TV+ | D14: Nein
C15: Joyn+ | D15: Nein
C16: MagentaTV | D16: Nein
B17: Streaming Musik
C18: Spotify | D18: Nein
C19: Apple Music | D19: Nein
C20: Amazon Music | D20: Nein
C21: Deezer | D21: Nein
C22: YouTube Music | D22: Nein
C23: Tidal | D23: Nein
B24: Fitness
C25: McFit / RSG Group | D25: Nein
C26: FitX | D26: Nein
C27: Urban Sports Club | D27: Nein
C28: Gymondo | D28: Nein
C29: Peloton | D29: Nein
C30: EGYM Wellpass | D30: Nein
B31: Software
C32: Adobe Creative Cloud | D32: Nein
C33: Microsoft 365 | D33: Nein
C34: Canva Pro | D34: Nein
C35: Notion | D35: Nein
C36: 1Password | D36: Nein
C37: Evernote | D37: Nein
C38: Todoist Premium | D38: Nein
B39: Cloud-Speicher
C40: iCloud+ | D40: Nein
C41: Google One | D41: Nein
...

Sheet Anleitung
B1: 📖 AboRadar – Anleitung
B3: 🚀 In 3 Schritten zum Abo-Überblick
B5: Schritt 1: Abos finden
B6: Gehe zum Tab "Abo-Finder" und arbeite die Checkliste durch.
B7: Vorher empfehlen wir: Kontoauszuege der letzten 3 Monate checken,
B8: E-Mail nach "Rechnung" oder "Abonnement" durchsuchen,
B9: und App-Store Abos prüfen (iPhone/Android).
B11: Schritt 2: Abos eintragen
B12: Wechsle zum Tab "Abo-Tracker" und trage deine Abos ein.
B13: Wähle für jedes Abo Kategorie, Kosten und Status aus den Dropdowns.
B14: Markiere Abos die du nicht mehr nutzt als "Ungenutzt" - sie werden rot.
B16: Schritt 3: Dashboard ansehen
... B50: Made with ❤️ by AboRadar – Kein Abo für den Abo-Tracker. Versprochen.
